Workbook

Sheet Início
B1: ⬢ CEMP · Banco de Soluções
B2: Diretoria de Pesquisa e Desenvolvimento · Centro de Empreendedorismo da UFC
B5: COMO FUNCIONA
B6: 1 Cadastre a fonte | E6: 2 Registre o problema | H6: 3 Registre a solução | K6: 4 Acompanhe
B7: Em 'Fontes e Parcerias', registre a EJ, o projeto de extensão ou a empresa de onde veio a ideia. Cada uma ganha um ID (FNT-001…). | E7: Na aba de Problemas da área (Geral ou um projeto), descreva o problema — real ou potencial — e avalie Impacto × Probabilidade. | H7: Na aba de Soluções, escolha o problema e a fonte nas listas, explique como implantar e anexe dados e links. | K7: O Painel mostra cobertura, prioridades, quick wins e alertas. Anote reuniões em 'Conversas' para não perder aprendizados.
B9: MAPA DA PLANILHA (clique no nome para ir até a aba)
B10: Painel | E10: Resumo automático: números por área, prioridades, quick wins, cobertura e alertas.
B11: Fontes e Parcerias | E11: Cadastro das EJs, projetos de extensão e empresas de onde vêm as ideias (IDs FNT-###).
B12: Conversas | E12: Diário das reuniões e conversas com as fontes: aprendizados, próximos passos e prazos.
B13: Geral - Problemas | E13: Problemas (reais ou potenciais) de: Geral (CEMP inteiro) · IDs GER-P###.
B14: Geral - Soluções | E14: Soluções encontradas para: Geral (CEMP inteiro) · IDs GER-S###, com fonte e passo a passo.
B15: Mentoring - Problemas | E15: Problemas (reais ou potenciais) de: Mentoring · IDs MEN-P###.
B16: Mentoring - Soluções | E16: Soluções encontradas para: Mentoring · IDs MEN-S###, com fonte e passo a passo.
B17: Feira - Problemas | E17: Problemas (reais ou potenciais) de: Feira de Empreendedorismo · IDs FEI-P###.
B18: Feira - Soluções | E18: Soluções encontradas para: Feira de Empreendedorismo · IDs FEI-S###, com fonte e passo a passo.
B19: Inova - Problemas | E19: Problemas (reais ou potenciais) de: Inova (hackathons) · IDs INO-P###.
B20: Inova - Soluções | E20: Soluções encontradas para: Inova (hackathons) · IDs INO-S###, com fonte e passo a passo.
B21: Sensibilizando - Problemas | E21: Problemas (reais ou potenciais) de: Sensibilizando (escolas) · IDs SEN-P###.
... B23: Listas | E23: Opções dos menus suspensos — edite aqui para personalizar categorias, diretorias, status etc.
B25: REGRAS DE CÁLCULO (automáticas — não digite nessas colunas)
B26: Score do problema | E26: Impacto (1–5) × Probabilidade (1–5) = de 1 a 25.
B27: Crítica | E27: Score de 15 a 25 → problema que precisa de solução primeiro.
B28: Alta | E28: Score de 9 a 14.
B29: Média | E29: Score de 4 a 8.
B30: Baixa | E30: Score de 1 a 3.
B31: Análise da solução | E31: Cruza Impacto esperado × Esforço: ⚡ Quick win (alto impacto, baixo esforço) · 🚀 Alto retorno · 🎯 Estratégica (alto/alto) · ⚖ Equilibrada · ⏳ Baixo retorno.
B32: Follow-up | E32: ⚠ Atrasado quando a data já passou; 'Esta semana' quando faltam 7 dias ou menos.
B34: LEGENDA E DICAS
B35: Célula branca / creme | E35: Você preenche.
B36: Fundo azul-acinzentado | E36: Automático — não digite; a fórmula faz o trabalho.
B37: Linha amarela [EXEMPLO] | E37: Modelo de preenchimento na 1ª linha de cada aba — apague ou sobrescreva ao começar.
B38: ID cinza (ex.: GER-P001) | E38: Fixo — não altere. Ele liga problema ↔ solução ↔ fonte, mesmo se você ordenar ou filtrar.
B39: • Use os filtros do cabeçalho (setinhas) para achar problemas críticos, soluções 'Quick win' ou fontes com follow-up atrasado.
B40: • Cada aba vem com 100 linhas prontas (Fontes: 150 · Conversas: 200). Para mais, copie a última linha e cole abaixo; o Painel lê até a linha 500.
B41: • A coluna 'Rótulo p/ vínculo' (final das abas de Problemas e Fontes) fica agrupada/oculta e alimenta as listas — clique no [+] para ver, mas não apague.
B42: • Passe o mouse (ou toque) nos cabeçalhos com o triângulo vermelho para ver a explicação de cada campo.

Sheet Painel
B1: ⬢ CEMP · Painel de Soluções
B2: Resumo automático de todo o banco de dados — atualiza sozinho conforme vocês preenchem as abas. | M2: ← Início
B5: PROBLEMAS CADASTRADOS | D5: CRÍTICOS SEM SOLUÇÃO | F5: SOLUÇÕES CADASTRADAS | H5: SOLUÇÕES IMPLANTADAS | J5: ORGANIZAÇÕES MAPEADAS | L5: FOLLOW-UPS ATRASADOS
B6: =D16 -> 5 | D6: =COUNTIFS('Geral - Problemas'!$J$5:$J$500,"Crítica",'Geral - Problemas'!$N$5:$N$500,0)+COUNTIFS('Mentoring - Problemas'!$J$5:$J$500,"Crítica",'Mentoring - Problemas'!$N$5:$N$500,0)+COUNTIFS('Feira - Problemas'!$J$5:$J$500,"Crítica",'Feira - Problemas'!$N$5:$N$500,0)+COUNTIFS('Inova - Problemas'!$J$5:$J$500,"Crítica",'Inova - Problemas'!$N$5:$N$500,0)+COUNTIFS('Sensibilizando - Problemas'!$J$5:$J$500,"Crítica",'Sensibilizando - Problemas'!$N$5:$N$500,0) -> 0 | F6: =J16 -> 5 | H6: =M16 -> 0 | J6: =COUNTA('Fontes e Parcerias'!$B$5:$B$500) -> 1 | L6: =COUNTIF('Fontes e Parcerias'!$P$5:$P$500,"*Atrasado*")+COUNTIF(Conversas!$K$5:$K$500,"*Atrasado*") -> 0
B9: VISÃO POR ÁREA
B10: Área | D10: Problemas | E10: Ocorrendo hoje | F10: Críticos + Altos | G10: Resolvidos | H10: Sem solução ainda | I10: Cobertura (com solução) | J10: Soluções | K10: Quick wins | L10: Em implantação | M10: Implantadas
B11: Geral | D11: =COUNTA('Geral - Problemas'!$B$5:$B$500) -> 1 | E11: =COUNTIF('Geral - Problemas'!$E$5:$E$500,"Ocorrendo hoje") -> 1 | F11: =COUNTIF('Geral - Problemas'!$J$5:$J$500,"Crítica")+COUNTIF('Geral - Problemas'!$J$5:$J$500,"Alta") -> 1 | G11: =COUNTIF('Geral - Problemas'!$M$5:$M$500,"Resolvido") -> 0 | H11: =D11-COUNTIF('Geral - Problemas'!$N$5:$N$500,">0") -> 0 | I11: =IF(D11=0,0,1-H11/D11) -> 1 | J11: =COUNTA('Geral - Soluções'!$B$5:$B$500) -> 1 | K11: =COUNTIF('Geral - Soluções'!$M$5:$M$500,"*Quick win*") -> 1 | L11: =COUNTIF('Geral - Soluções'!$P$5:$P$500,"Em implantação") -> 0 | M11: =COUNTIF('Geral - Soluções'!$P$5:$P$500,"Implantada") -> 0
B12: Mentoring | D12: =COUNTA('Mentoring - Problemas'!$B$5:$B$500) -> 1 | E12: =COUNTIF('Mentoring - Problemas'!$E$5:$E$500,"Ocorrendo hoje") -> 1 | F12: =COUNTIF('Mentoring - Problemas'!$J$5:$J$500,"Crítica")+COUNTIF('Mentoring - Problemas'!$J$5:$J$500,"Alta") -> 1 | G12: =COUNTIF('Mentoring - Problemas'!$M$5:$M$500,"Resolvido") -> 0 | H12: =D12-COUNTIF('Mentoring - Problemas'!$N$5:$N$500,">0") -> 0 | I12: =IF(D12=0,0,1-H12/D12) -> 1 | J12: =COUNTA('Mentoring - Soluções'!$B$5:$B$500) -> 1 | K12: =COUNTIF('Mentoring - Soluções'!$M$5:$M$500,"*Quick win*") -> 0 | L12: =COUNTIF('Mentoring - Soluções'!$P$5:$P$500,"Em implantação") -> 0 | M12: =COUNTIF('Mentoring - Soluções'!$P$5:$P$500,"Implantada") -> 0
B13: Feira | D13: =COUNTA('Feira - Problemas'!$B$5:$B$500) -> 1 | E13: =COUNTIF('Feira - Problemas'!$E$5:$E$500,"Ocorrendo hoje") -> 1 | F13: =COUNTIF('Feira - Problemas'!$J$5:$J$500,"Crítica")+COUNTIF('Feira - Problemas'!$J$5:$J$500,"Alta") -> 1 | G13: =COUNTIF('Feira - Problemas'!$M$5:$M$500,"Resolvido") -> 0 | H13: =D13-COUNTIF('Feira - Problemas'!$N$5:$N$500,">0") -> 0 | I13: =IF(D13=0,0,1-H13/D13) -> 1 | J13: =COUNTA('Feira - Soluções'!$B$5:$B$500) -> 1 | K13: =COUNTIF('Feira - Soluções'!$M$5:$M$500,"*Quick win*") -> 0 | L13: =COUNTIF('Feira - Soluções'!$P$5:$P$500,"Em implantação") -> 0 | M13: =COUNTIF('Feira - Soluções'!$P$5:$P$500,"Implantada") -> 0
B14: Inova | D14: =COUNTA('Inova - Problemas'!$B$5:$B$500) -> 1 | E14: =COUNTIF('Inova - Problemas'!$E$5:$E$500,"Ocorrendo hoje") -> 0 | F14: =COUNTIF('Inova - Problemas'!$J$5:$J$500,"Crítica")+COUNTIF('Inova - Problemas'!$J$5:$J$500,"Alta") -> 1 | G14: =COUNTIF('Inova - Problemas'!$M$5:$M$500,"Resolvido") -> 0 | H14: =D14-COUNTIF('Inova - Problemas'!$N$5:$N$500,">0") -> 0 | I14: =IF(D14=0,0,1-H14/D14) -> 1 | J14: =COUNTA('Inova - Soluções'!$B$5:$B$500) -> 1 | K14: =COUNTIF('Inova - Soluções'!$M$5:$M$500,"*Quick win*") -> 0 | L14: =COUNTIF('Inova - Soluções'!$P$5:$P$500,"Em implantação") -> 0 | M14: =COUNTIF('Inova - Soluções'!$P$5:$P$500,"Implantada") -> 0
B15: Sensibilizando | D15: =COUNTA('Sensibilizando - Problemas'!$B$5:$B$500) -> 1 | E15: =COUNTIF('Sensibilizando - Problemas'!$E$5:$E$500,"Ocorrendo hoje") -> 1 | F15: =COUNTIF('Sensibilizando - Problemas'!$J$5:$J$500,"Crítica")+COUNTIF('Sensibilizando - Problemas'!$J$5:$J$500,"Alta") -> 1 | G15: =COUNTIF('Sensibilizando - Problemas'!$M$5:$M$500,"Resolvido") -> 0 | H15: =D15-COUNTIF('Sensibilizando - Problemas'!$N$5:$N$500,">0") -> 0 | I15: =IF(D15=0,0,1-H15/D15) -> 1 | J15: =COUNTA('Sensibilizando - Soluções'!$B$5:$B$500) -> 1 | K15: =COUNTIF('Sensibilizando - Soluções'!$M$5:$M$500,"*Quick win*") -> 0 | L15: =COUNTIF('Sensibilizando - Soluções'!$P$5:$P$500,"Em implantação") -> 1 | M15: =COUNTIF('Sensibilizando - Soluções'!$P$5:$P$500,"Implantada") -> 0
B16: TOTAL | D16: =SUM(D11:D15) -> 5 | E16: =SUM(E11:E15) -> 4 | F16: =SUM(F11:F15) -> 5 | G16: =SUM(G11:G15) -> 0 | H16: =SUM(H11:H15) -> 0 | I16: =IF(D16=0,0,1-H16/D16) -> 1 | J16: =SUM(J11:J15) -> 5 | K16: =SUM(K11:K15) -> 1 | L16: =SUM(L11:L15) -> 1 | M16: =SUM(M11:M15) -> 0
B19: PRIORIDADE DOS PROBLEMAS POR ÁREA
B20: Área | D20: Crítica | E20: Alta | F20: Média | G20: Baixa
B21: Geral | D21: =COUNTIF('Geral - Problemas'!$J$5:$J$500,"Crítica") -> 1 | E21: =COUNTIF('Geral - Problemas'!$J$5:$J$500,"Alta") -> 0 | F21: =COUNTIF('Geral - Problemas'!$J$5:$J$500,"Média") -> 0 | G21: =COUNTIF('Geral - Problemas'!$J$5:$J$500,"Baixa") -> 0
B22: Mentoring | D22: =COUNTIF('Mentoring - Problemas'!$J$5:$J$500,"Crítica") -> 0 | E22: =COUNTIF('Mentoring - Problemas'!$J$5:$J$500,"Alta") -> 1 | F22: =COUNTIF('Mentoring - Problemas'!$J$5:$J$500,"Média") -> 0 | G22: =COUNTIF('Mentoring - Problemas'!$J$5:$J$500,"Baixa") -> 0
B23: Feira | D23: =COUNTIF('Feira - Problemas'!$J$5:$J$500,"Crítica") -> 1 | E23: =COUNTIF('Feira - Problemas'!$J$5:$J$500,"Alta") -> 0 | F23: =COUNTIF('Feira - Problemas'!$J$5:$J$500,"Média") -> 0 | G23: =COUNTIF('Feira - Problemas'!$J$5:$J$500,"Baixa") -> 0
B24: Inova | D24: =COUNTIF('Inova - Problemas'!$J$5:$J$500,"Crítica") -> 0 | E24: =COUNTIF('Inova - Problemas'!$J$5:$J$500,"Alta") -> 1 | F24: =COUNTIF('Inova - Problemas'!$J$5:$J$500,"Média") -> 0 | G24: =COUNTIF('Inova - Problemas'!$J$5:$J$500,"Baixa") -> 0
B25: Sensibilizando | D25: =COUNTIF('Sensibilizando - Problemas'!$J$5:$J$500,"Crítica") -> 0 | E25: =COUNTIF('Sensibilizando - Problemas'!$J$5:$J$500,"Alta") -> 1 | F25: =COUNTIF('Sensibilizando - Problemas'!$J$5:$J$500,"Média") -> 0 | G25: =COUNTIF('Sensibilizando - Problemas'!$J$5:$J$500,"Baixa") -> 0
B34: SOLUÇÕES POR STATUS DE IMPLANTAÇÃO
B35: Status | D35: Qtd.
B36: Ideia | D36: =COUNTIF('Geral - Soluções'!$P$5:$P$500,"Ideia")+COUNTIF('Mentoring - Soluções'!$P$5:$P$500,"Ideia")+COUNTIF('Feira - Soluções'!$P$5:$P$500,"Ideia")+COUNTIF('Inova - Soluções'!$P$5:$P$500,"Ideia")+COUNTIF('Sensibilizando - Soluções'!$P$5:$P$500,"Ideia") -> 1
B37: Em análise | D37: =COUNTIF('Geral - Soluções'!$P$5:$P$500,"Em análise")+COUNTIF('Mentoring - Soluções'!$P$5:$P$500,"Em análise")+COUNTIF('Feira - Soluções'!$P$5:$P$500,"Em análise")+COUNTIF('Inova - Soluções'!$P$5:$P$500,"Em análise")+COUNTIF('Sensibilizando - Soluções'!$P$5:$P$500,"Em análise") -> 2
B38: Aprovada | D38: =COUNTIF('Geral - Soluções'!$P$5:$P$500,"Aprovada")+COUNTIF('Mentoring - Soluções'!$P$5:$P$500,"Aprovada")+COUNTIF('Feira - Soluções'!$P$5:$P$500,"Aprovada")+COUNTIF('Inova - Soluções'!$P$5:$P$500,"Aprovada")+COUNTIF('Sensibilizando - Soluções'!$P$5:$P$500,"Aprovada") -> 1
B39: Em implantação | D39: =COUNTIF('Geral - Soluções'!$P$5:$P$500,"Em implantação")+COUNTIF('Mentoring - Soluções'!$P$5:$P$500,"Em implantação")+COUNTIF('Feira - Soluções'!$P$5:$P$500,"Em implantação")+COUNTIF('Inova - Soluções'!$P$5:$P$500,"Em implantação")+COUNTIF('Sensibilizando - Soluções'!$P$5:$P$500,"Em implantação") -> 1
B40: Implantada | D40: =COUNTIF('Geral - Soluções'!$P$5:$P$500,"Implantada")+COUNTIF('Mentoring - Soluções'!$P$5:$P$500,"Implantada")+COUNTIF('Feira - Soluções'!$P$5:$P$500,"Implantada")+COUNTIF('Inova - Soluções'!$P$5:$P$500,"Implantada")+COUNTIF('Sensibilizando - Soluções'!$P$5:$P$500,"Implantada") -> 0
B41: Descartada | D41: =COUNTIF('Geral - Soluções'!$P$5:$P$500,"Descartada")+COUNTIF('Mentoring - Soluções'!$P$5:$P$500,"Descartada")+COUNTIF('Feira - Soluções'!$P$5:$P$500,"Descartada")+COUNTIF('Inova - Soluções'!$P$5:$P$500,"Descartada")+COUNTIF('Sensibilizando - Soluções'!$P$5:$P$500,"Descartada") -> 0
B44: ORGANIZAÇÕES POR NÍVEL DE RELAÇÃO
B45: Nível | D45: Qtd.
B46: Mapeada | D46: =COUNTIF('Fontes e Parcerias'!$L$5:$L$500,"Mapeada") -> 0
B47: Contato iniciado | D47: =COUNTIF('Fontes e Parcerias'!$L$5:$L$500,"Contato iniciado") -> 0
B48: Conversa realizada | D48: =COUNTIF('Fontes e Parcerias'!$L$5:$L$500,"Conversa realizada") -> 1
B49: Parceria em negociação | D49: =COUNTIF('Fontes e Parcerias'!$L$5:$L$500,"Parceria em negociação") -> 0
B50: Parceria ativa | D50: =COUNTIF('Fontes e Parcerias'!$L$5:$L$500,"Parceria ativa") -> 0
B51: Sem retorno | D51: =COUNTIF('Fontes e Parcerias'!$L$5:$L$500,"Sem retorno") -> 0
B53: Como ler: 'Cobertura' = % dos problemas que já têm pelo menos uma solução vinculada. 'Críticos sem solução' são os primeiros da fila. Os números incluem as linhas de exemplo até que sejam apagadas.

Sheet Fontes e Parcerias
A1: ⬢ CEMP · Fontes e Parcerias
A2: ← Início | B2: ="Banco de organizações (EJs, extensão, empresas) de onde vêm as ideias · "&COUNTA(B5:B500)&" registro(s)" -> Banco de organizações (EJs, extensão, empresas) de onde vêm as ideias · 1 registro(s)
A3: QUEM É | G3: CONTATO E RELAÇÃO COM O CEMP | K3: RELACIONAMENTO | Q3: RESULTADO
A4: ID | B4: Organização / projeto | C4: Tipo | D4: Instituição / universidade | E4: Cidade / UF | F4: Área de atuação / especialidade | G4: Projeto do CEMP relacionado | H4: Pessoa de contato | I4: Cargo / função | J4: E-mail / WhatsApp | K4: Instagram / site | L4: Nível de relação | M4: Nº de conversas (auto) | N4: Último contato (auto) | O4: Próximo contato (data) | P4: Follow-up (auto) | Q4: Soluções trazidas (auto) | R4: O que aprendemos com eles | S4: Rótulo p/ vínculo (auto)
A5: FNT-001 | B5: [EXEMPLO] Empresa Júnior de Administração – Universidade X | C5: Empresa Júnior | D5: Universidade X | E5: Cidade/UF | F5: Gestão de pessoas e projetos | G5: Geral (CEMP inteiro) | H5: Nome do contato | I5: Diretor(a) de Pessoas | J5: email@exemplo.com · (85) 90000-0000 | K5: @perfil_da_ej | L5: Conversa realizada | M5: =IF(B5="","",COUNTIF(Conversas!$B$5:$B$500,A5&"*")) -> 1 | N5: =IF(B5="","",IF(M5=0,"",_xlfn.MAXIFS(Conversas!$C$5:$C$500,Conversas!$B$5:$B$500,A5&"*"))) -> 46290 | O5: 46307 | P5: =IF(B5="","",IF(O5="","Sem data",IF(O5<TODAY(),"⚠ Atrasado",IF(O5-TODAY()<=7,"Esta semana","Agendado")))) -> Agendado | Q5: =IF(B5="","",COUNTIF('Geral - Soluções'!$E$5:$E$500,A5&"*")+COUNTIF('Mentoring - Soluções'!$E$5:$E$500,A5&"*")+COUNTIF('Feira - Soluções'!$E$5:$E$500,A5&"*")+COUNTIF('Inova - Soluções'!$E$5:$E$500,A5&"*")+COUNTIF('Sensibilizando - Soluções'!$E$5:$E$500,A5&"*")) -> 5 | R5: Resumo do que aprendemos com eles (linha de exemplo). | S5: =IF(B5="","",A5&" · "&B5) -> FNT-001 · [EXEMPLO] Empresa Júnior de Administração – Universidade X
A6: FNT-002 | M6: =IF(B6="","",COUNTIF(Conversas!$B$5:$B$500,A6&"*")) | N6: =IF(B6="","",IF(M6=0,"",_xlfn.MAXIFS(Conversas!$C$5:$C$500,Conversas!$B$5:$B$500,A6&"*"))) | P6: =IF(B6="","",IF(O6="","Sem data",IF(O6<TODAY(),"⚠ Atrasado",IF(O6-TODAY()<=7,"Esta semana","Agendado")))) | Q6: =IF(B6="","",COUNTIF('Geral - Soluções'!$E$5:$E$500,A6&"*")+COUNTIF('Mentoring - Soluções'!$E$5:$E$500,A6&"*")+COUNTIF('Feira - Soluções'!$E$5:$E$500,A6&"*")+COUNTIF('Inova - Soluções'!$E$5:$E$500,A6&"*")+COUNTIF('Sensibilizando - Soluções'!$E$5:$E$500,A6&"*")) | S6: =IF(B6="","",A6&" · "&B6)
A7: FNT-003 | M7: =IF(B7="","",COUNTIF(Conversas!$B$5:$B$500,A7&"*")) | N7: =IF(B7="","",IF(M7=0,"",_xlfn.MAXIFS(Conversas!$C$5:$C$500,Conversas!$B$5:$B$500,A7&"*"))) | P7: =IF(B7="","",IF(O7="","Sem data",IF(O7<TODAY(),"⚠ Atrasado",IF(O7-TODAY()<=7,"Esta semana","Agendado")))) | Q7: =IF(B7="","",COUNTIF('Geral - Soluções'!$E$5:$E$500,A7&"*")+COUNTIF('Mentoring - Soluções'!$E$5:$E$500,A7&"*")+COUNTIF('Feira - Soluções'!$E$5:$E$500,A7&"*")+COUNTIF('Inova - Soluções'!$E$5:$E$500,A7&"*")+COUNTIF('Sensibilizando - Soluções'!$E$5:$E$500,A7&"*")) | S7: =IF(B7="","",A7&" · "&B7)
A8: FNT-004 | M8: =IF(B8="","",COUNTIF(Conversas!$B$5:$B$500,A8&"*")) | N8: =IF(B8="","",IF(M8=0,"",_xlfn.MAXIFS(Conversas!$C$5:$C$500,Conversas!$B$5:$B$500,A8&"*"))) | P8: =IF(B8="","",IF(O8="","Sem data",IF(O8<TODAY(),"⚠ Atrasado",IF(O8-TODAY()<=7,"Esta semana","Agendado")))) | Q8: =IF(B8="","",COUNTIF('Geral - Soluções'!$E$5:$E$500,A8&"*")+COUNTIF('Mentoring - Soluções'!$E$5:$E$500,A8&"*")+COUNTIF('Feira - Soluções'!$E$5:$E$500,A8&"*")+COUNTIF('Inova - Soluções'!$E$5:$E$500,A8&"*")+COUNTIF('Sensibilizando - Soluções'!$E$5:$E$500,A8&"*")) | S8: =IF(B8="","",A8&" · "&B8)
A9: FNT-005 | M9: =IF(B9="","",COUNTIF(Conversas!$B$5:$B$500,A9&"*")) | N9: =IF(B9="","",IF(M9=0,"",_xlfn.MAXIFS(Conversas!$C$5:$C$500,Conversas!$B$5:$B$500,A9&"*"))) | P9: =IF(B9="","",IF(O9="","Sem data",IF(O9<TODAY(),"⚠ Atrasado",IF(O9-TODAY()<=7,"Esta semana","Agendado")))) | Q9: =IF(B9="","",COUNTIF('Geral - Soluções'!$E$5:$E$500,A9&"*")+COUNTIF('Mentoring - Soluções'!$E$5:$E$500,A9&"*")+COUNTIF('Feira - Soluções'!$E$5:$E$500,A9&"*")+COUNTIF('Inova - Soluções'!$E$5:$E$500,A9&"*")+COUNTIF('Sensibilizando - Soluções'!$E$5:$E$500,A9&"*")) | S9: =IF(B9="","",A9&" · "&B9)
A10: FNT-006 | M10: =IF(B10="","",COUNTIF(Conversas!$B$5:$B$500,A10&"*")) | N10: =IF(B10="","",IF(M10=0,"",_xlfn.MAXIFS(Conversas!$C$5:$C$500,Conversas!$B$5:$B$500,A10&"*"))) | P10: =IF(B10="","",IF(O10="","Sem data",IF(O10<TODAY(),"⚠ Atrasado",IF(O10-TODAY()<=7,"Esta semana","Agendado")))) | Q10: =IF(B10="","",COUNTIF('Geral - Soluções'!$E$5:$E$500,A10&"*")+COUNTIF('Mentoring - Soluções'!$E$5:$E$500,A10&"*")+COUNTIF('Feira - Soluções'!$E$5:$E$500,A10&"*")+COUNTIF('Inova - Soluções'!$E$5:$E$500,A10&"*")+COUNTIF('Sensibilizando - Soluções'!$E$5:$E$500,A10&"*")) | S10: =IF(B10="","",A10&" · "&B10)
A11: FNT-007 | M11: =IF(B11="","",COUNTIF(Conversas!$B$5:$B$500,A11&"*")) | N11: =IF(B11="","",IF(M11=0,"",_xlfn.MAXIFS(Conversas!$C$5:$C$500,Conversas!$B$5:$B$500,A11&"*"))) | P11: =IF(B11="","",IF(O11="","Sem data",IF(O11<TODAY(),"⚠ Atrasado",IF(O11-TODAY()<=7,"Esta semana","Agendado")))) | Q11: =IF(B11="","",COUNTIF('Geral - Soluções'!$E$5:$E$500,A11&"*")+COUNTIF('Mentoring - Soluções'!$E$5:$E$500,A11&"*")+COUNTIF('Feira - Soluções'!$E$5:$E$500,A11&"*")+COUNTIF('Inova - Soluções'!$E$5:$E$500,A11&"*")+COUNTIF('Sensibilizando - Soluções'!$E$5:$E$500,A11&"*")) | S11: =IF(B11="","",A11&" · "&B11)
A12: FNT-008 | M12: =IF(B12="","",COUNTIF(Conversas!$B$5:$B$500,A12&"*")) | N12: =IF(B12="","",IF(M12=0,"",_xlfn.MAXIFS(Conversas!$C$5:$C$500,Conversas!$B$5:$B$500,A12&"*"))) | P12: =IF(B12="","",IF(O12="","Sem data",IF(O12<TODAY(),"⚠ Atrasado",IF(O12-TODAY()<=7,"Esta semana","Agendado")))) | Q12: =IF(B12="","",COUNTIF('Geral - Soluções'!$E$5:$E$500,A12&"*")+COUNTIF('Mentoring - Soluções'!$E$5:$E$500,A12&"*")+COUNTIF('Feira - Soluções'!$E$5:$E$500,A12&"*")+COUNTIF('Inova - Soluções'!$E$5:$E$500,A12&"*")+COUNTIF('Sensibilizando - Soluções'!$E$5:$E$500,A12&"*")) | S12: =IF(B12="","",A12&" · "&B12)
A13: FNT-009 | M13: =IF(B13="","",COUNTIF(Conversas!$B$5:$B$500,A13&"*")) | N13: =IF(B13="","",IF(M13=0,"",_xlfn.MAXIFS(Conversas!$C$5:$C$500,Conversas!$B$5:$B$500,A13&"*"))) | P13: =IF(B13="","",IF(O13="","Sem data",IF(O13<TODAY(),"⚠ Atrasado",IF(O13-TODAY()<=7,"Esta semana","Agendado")))) | Q13: =IF(B13="","",COUNTIF('Geral - Soluções'!$E$5:$E$500,A13&"*")+COUNTIF('Mentoring - Soluções'!$E$5:$E$500,A13&"*")+COUNTIF('Feira - Soluções'!$E$5:$E$500,A13&"*")+COUNTIF('Inova - Soluções'!$E$5:$E$500,A13&"*")+COUNTIF('Sensibilizando - Soluções'!$E$5:$E$500,A13&"*")) | S13: =IF(B13="","",A13&" · "&B13)
A14: FNT-010 | M14: =IF(B14="","",COUNTIF(Conversas!$B$5:$B$500,A14&"*")) | N14: =IF(B14="","",IF(M14=0,"",_xlfn.MAXIFS(Conversas!$C$5:$C$500,Conversas!$B$5:$B$500,A14&"*"))) | P14: =IF(B14="","",IF(O14="","Sem data",IF(O14<TODAY(),"⚠ Atrasado",IF(O14-TODAY()<=7,"Esta semana","Agendado")))) | Q14: =IF(B14="","",COUNTIF('Geral - Soluções'!$E$5:$E$500,A14&"*")+COUNTIF('Mentoring - Soluções'!$E$5:$E$500,A14&"*")+COUNTIF('Feira - Soluções'!$E$5:$E$500,A14&"*")+COUNTIF('Inova - Soluções'!$E$5:$E$500,A14&"*")+COUNTIF('Sensibilizando - Soluções'!$E$5:$E$500,A14&"*")) | S14: =IF(B14="","",A14&" · "&B14)
A15: FNT-011 | M15: =IF(B15="","",COUNTIF(Conversas!$B$5:$B$500,A15&"*")) | N15: =IF(B15="","",IF(M15=0,"",_xlfn.MAXIFS(Conversas!$C$5:$C$500,Conversas!$B$5:$B$500,A15&"*"))) | P15: =IF(B15="","",IF(O15="","Sem data",IF(O15<TODAY(),"⚠ Atrasado",IF(O15-TODAY()<=7,"Esta semana","Agendado")))) | Q15: =IF(B15="","",COUNTIF('Geral - Soluções'!$E$5:$E$500,A15&"*")+COUNTIF('Mentoring - Soluções'!$E$5:$E$500,A15&"*")+COUNTIF('Feira - Soluções'!$E$5:$E$500,A15&"*")+COUNTIF('Inova - Soluções'!$E$5:$E$500,A15&"*")+COUNTIF('Sensibilizando - Soluções'!$E$5:$E$500,A15&"*")) | S15: =IF(B15="","",A15&" · "&B15)
A16: FNT-012 | M16: =IF(B16="","",COUNTIF(Conversas!$B$5:$B$500,A16&"*")) | N16: =IF(B16="","",IF(M16=0,"",_xlfn.MAXIFS(Conversas!$C$5:$C$500,Conversas!$B$5:$B$500,A16&"*"))) | P16: =IF(B16="","",IF(O16="","Sem data",IF(O16<TODAY(),"⚠ Atrasado",IF(O16-TODAY()<=7,"Esta semana","Agendado")))) | Q16: =IF(B16="","",COUNTIF('Geral - Soluções'!$E$5:$E$500,A16&"*")+COUNTIF('Mentoring - Soluções'!$E$5:$E$500,A16&"*")+COUNTIF('Feira - Soluções'!$E$5:$E$500,A16&"*")+COUNTIF('Inova - Soluções'!$E$5:$E$500,A16&"*")+COUNTIF('Sensibilizando - Soluções'!$E$5:$E$500,A16&"*")) | S16: =IF(B16="","",A16&" · "&B16)
A17: FNT-013 | M17: =IF(B17="","",COUNTIF(Conversas!$B$5:$B$500,A17&"*")) | N17: =IF(B17="","",IF(M17=0,"",_xlfn.MAXIFS(Conversas!$C$5:$C$500,Conversas!$B$5:$B$500,A17&"*"))) | P17: =IF(B17="","",IF(O17="","Sem data",IF(O17<TODAY(),"⚠ Atrasado",IF(O17-TODAY()<=7,"Esta semana","Agendado")))) | Q17: =IF(B17="","",COUNTIF('Geral - Soluções'!$E$5:$E$500,A17&"*")+COUNTIF('Mentoring - Soluções'!$E$5:$E$500,A17&"*")+COUNTIF('Feira - Soluções'!$E$5:$E$500,A17&"*")+COUNTIF('Inova - Soluções'!$E$5:$E$500,A17&"*")+COUNTIF('Sensibilizando - Soluções'!$E$5:$E$500,A17&"*")) | S17: =IF(B17="","",A17&" · "&B17)
... A154: FNT-150 | M154: =IF(B154="","",COUNTIF(Conversas!$B$5:$B$500,A154&"*")) | N154: =IF(B154="","",IF(M154=0,"",_xlfn.MAXIFS(Conversas!$C$5:$C$500,Conversas!$B$5:$B$500,A154&"*"))) | P154: =IF(B154="","",IF(O154="","Sem data",IF(O154<TODAY(),"⚠ Atrasado",IF(O154-TODAY()<=7,"Esta semana","Agendado")))) | Q154: =IF(B154="","",COUNTIF('Geral - Soluções'!$E$5:$E$500,A154&"*")+COUNTIF('Mentoring - Soluções'!$E$5:$E$500,A154&"*")+COUNTIF('Feira - Soluções'!$E$5:$E$500,A154&"*")+COUNTIF('Inova - Soluções'!$E$5:$E$500,A154&"*")+COUNTIF('Sensibilizando - Soluções'!$E$5:$E$500,A154&"*")) | S154: =IF(B154="","",A154&" · "&B154)

Sheet Conversas
A1: ⬢ CEMP · Conversas com as fontes
A2: ← Início | B2: ="Diário de reuniões e conversas: o que aprendemos e o que fazer depois · "&COUNTA(B5:B500)&" registro(s)" -> Diário de reuniões e conversas: o que aprendemos e o que fazer depois · 1 registro(s)
A3: A CONVERSA | F3: O QUE FICOU | H3: PRÓXIMOS PASSOS
A4: ID | B4: Organização | C4: Data | D4: Formato | E4: Quem do CEMP participou | F4: Assuntos discutidos | G4: Principais aprendizados | H4: Próximos passos | I4: Prazo do próximo passo | J4: Situação do passo | K4: Alerta (auto)
A5: CNV-001 | B5: FNT-001 · [EXEMPLO] Empresa Júnior de Administração – Universidade X | C5: 46290 | D5: Reunião online | E5: Diretor(a) de P&D + 1 membro | F5: Como funciona o onboarding e a retenção de membros na EJ. | G5: Registre aqui os pontos-chave e os números compartilhados (linha de exemplo). | H5: Enviar agradecimento e pedir o modelo de roteiro de 90 dias. | I5: 46300 | J5: Em andamento | K5: =IF(B5="","",IF(J5="Concluído","✔ Concluído",IF(I5="","Sem prazo",IF(I5<TODAY(),"⚠ Atrasado",IF(I5-TODAY()<=7,"Esta semana","No prazo"))))) -> Esta semana
A6: CNV-002 | K6: =IF(B6="","",IF(J6="Concluído","✔ Concluído",IF(I6="","Sem prazo",IF(I6<TODAY(),"⚠ Atrasado",IF(I6-TODAY()<=7,"Esta semana","No prazo")))))
A7: CNV-003 | K7: =IF(B7="","",IF(J7="Concluído","✔ Concluído",IF(I7="","Sem prazo",IF(I7<TODAY(),"⚠ Atrasado",IF(I7-TODAY()<=7,"Esta semana","No prazo")))))
A8: CNV-004 | K8: =IF(B8="","",IF(J8="Concluído","✔ Concluído",IF(I8="","Sem prazo",IF(I8<TODAY(),"⚠ Atrasado",IF(I8-TODAY()<=7,"Esta semana","No prazo")))))
A9: CNV-005 | K9: =IF(B9="","",IF(J9="Concluído","✔ Concluído",IF(I9="","Sem prazo",IF(I9<TODAY(),"⚠ Atrasado",IF(I9-TODAY()<=7,"Esta semana","No prazo")))))
A10: CNV-006 | K10: =IF(B10="","",IF(J10="Concluído","✔ Concluído",IF(I10="","Sem prazo",IF(I10<TODAY(),"⚠ Atrasado",IF(I10-TODAY()<=7,"Esta semana","No prazo")))))
A11: CNV-007 | K11: =IF(B11="","",IF(J11="Concluído","✔ Concluído",IF(I11="","Sem prazo",IF(I11<TODAY(),"⚠ Atrasado",IF(I11-TODAY()<=7,"Esta semana","No prazo")))))
A12: CNV-008 | K12: =IF(B12="","",IF(J12="Concluído","✔ Concluído",IF(I12="","Sem prazo",IF(I12<TODAY(),"⚠ Atrasado",IF(I12-TODAY()<=7,"Esta semana","No prazo")))))
A13: CNV-009 | K13: =IF(B13="","",IF(J13="Concluído","✔ Concluído",IF(I13="","Sem prazo",IF(I13<TODAY(),"⚠ Atrasado",IF(I13-TODAY()<=7,"Esta semana","No prazo")))))
A14: CNV-010 | K14: =IF(B14="","",IF(J14="Concluído","✔ Concluído",IF(I14="","Sem prazo",IF(I14<TODAY(),"⚠ Atrasado",IF(I14-TODAY()<=7,"Esta semana","No prazo")))))
A15: CNV-011 | K15: =IF(B15="","",IF(J15="Concluído","✔ Concluído",IF(I15="","Sem prazo",IF(I15<TODAY(),"⚠ Atrasado",IF(I15-TODAY()<=7,"Esta semana","No prazo")))))
A16: CNV-012 | K16: =IF(B16="","",IF(J16="Concluído","✔ Concluído",IF(I16="","Sem prazo",IF(I16<TODAY(),"⚠ Atrasado",IF(I16-TODAY()<=7,"Esta semana","No prazo")))))
A17: CNV-013 | K17: =IF(B17="","",IF(J17="Concluído","✔ Concluído",IF(I17="","Sem prazo",IF(I17<TODAY(),"⚠ Atrasado",IF(I17-TODAY()<=7,"Esta semana","No prazo")))))
... A204: CNV-200 | K204: =IF(B204="","",IF(J204="Concluído","✔ Concluído",IF(I204="","Sem prazo",IF(I204<TODAY(),"⚠ Atrasado",IF(I204-TODAY()<=7,"Esta semana","No prazo")))))

Sheet Geral - Problemas
A1: ⬢ CEMP · Geral — Problemas
A2: ← Início | B2: ="Problemas que o CEMP tem ou pode ter em: Geral (CEMP inteiro) · "&COUNTA(B5:B500)&" registro(s)" -> Problemas que o CEMP tem ou pode ter em: Geral (CEMP inteiro) · 1 registro(s)
A3: O PROBLEMA | G3: AVALIAÇÃO DE RISCO | K3: GESTÃO | O3: REGISTRO
A4: ID | B4: Título do problema | C4: Descrição detalhada | D4: Categoria | E4: Situação | F4: Etapa / momento em que ocorre | G4: Impacto (1–5) | H4: Probabilidade (1–5) | I4: Score (auto) | J4: Prioridade (auto) | K4: Evidência / como identificamos | L4: Diretoria responsável | M4: Status | N4: Soluções vinculadas (auto) | O4: Data de registro | P4: Registrado por | Q4: Observações | R4: Rótulo p/ vínculo (auto)
A5: GER-P001 | B5: [EXEMPLO] Baixa retenção de membros após o processo seletivo | C5: Parte dos aprovados deixa o CEMP nos primeiros meses por falta de vínculo, de clareza sobre o papel e de acompanhamento. | D5: Gestão de pessoas e engajamento | E5: Ocorrendo hoje | F5: Primeiros 90 dias do membro | G5: 4 | H5: 4 | I5: =IF(OR(G5="",H5=""),"",G5*H5) -> 16 | J5: =IF(I5="","",IF(I5>=15,"Crítica",IF(I5>=9,"Alta",IF(I5>=4,"Média","Baixa")))) -> Crítica | K5: Levantar desligamentos e feedback de saída do semestre anterior. | L5: Gestão de Pessoas | M5: Buscando solução | N5: =IF(B5="","",COUNTIF('Geral - Soluções'!$C$5:$C$500,A5&"*")) -> 1 | O5: 46293 | P5: Diretoria de P&D | Q5: Linha de exemplo — apague ou sobrescreva. | R5: =IF(B5="","",A5&" · "&B5) -> GER-P001 · [EXEMPLO] Baixa retenção de membros após o processo seletivo
A6: GER-P002 | I6: =IF(OR(G6="",H6=""),"",G6*H6) | J6: =IF(I6="","",IF(I6>=15,"Crítica",IF(I6>=9,"Alta",IF(I6>=4,"Média","Baixa")))) | N6: =IF(B6="","",COUNTIF('Geral - Soluções'!$C$5:$C$500,A6&"*")) | R6: =IF(B6="","",A6&" · "&B6)
A7: GER-P003 | I7: =IF(OR(G7="",H7=""),"",G7*H7) | J7: =IF(I7="","",IF(I7>=15,"Crítica",IF(I7>=9,"Alta",IF(I7>=4,"Média","Baixa")))) | N7: =IF(B7="","",COUNTIF('Geral - Soluções'!$C$5:$C$500,A7&"*")) | R7: =IF(B7="","",A7&" · "&B7)
A8: GER-P004 | I8: =IF(OR(G8="",H8=""),"",G8*H8) | J8: =IF(I8="","",IF(I8>=15,"Crítica",IF(I8>=9,"Alta",IF(I8>=4,"Média","Baixa")))) | N8: =IF(B8="","",COUNTIF('Geral - Soluções'!$C$5:$C$500,A8&"*")) | R8: =IF(B8="","",A8&" · "&B8)
A9: GER-P005 | I9: =IF(OR(G9="",H9=""),"",G9*H9) | J9: =IF(I9="","",IF(I9>=15,"Crítica",IF(I9>=9,"Alta",IF(I9>=4,"Média","Baixa")))) | N9: =IF(B9="","",COUNTIF('Geral - Soluções'!$C$5:$C$500,A9&"*")) | R9: =IF(B9="","",A9&" · "&B9)
A10: GER-P006 | I10: =IF(OR(G10="",H10=""),"",G10*H10) | J10: =IF(I10="","",IF(I10>=15,"Crítica",IF(I10>=9,"Alta",IF(I10>=4,"Média","Baixa")))) | N10: =IF(B10="","",COUNTIF('Geral - Soluções'!$C$5:$C$500,A10&"*")) | R10: =IF(B10="","",A10&" · "&B10)
A11: GER-P007 | I11: =IF(OR(G11="",H11=""),"",G11*H11) | J11: =IF(I11="","",IF(I11>=15,"Crítica",IF(I11>=9,"Alta",IF(I11>=4,"Média","Baixa")))) | N11: =IF(B11="","",COUNTIF('Geral - Soluções'!$C$5:$C$500,A11&"*")) | R11: =IF(B11="","",A11&" · "&B11)
A12: GER-P008 | I12: =IF(OR(G12="",H12=""),"",G12*H12) | J12: =IF(I12="","",IF(I12>=15,"Crítica",IF(I12>=9,"Alta",IF(I12>=4,"Média","Baixa")))) | N12: =IF(B12="","",COUNTIF('Geral - Soluções'!$C$5:$C$500,A12&"*")) | R12: =IF(B12="","",A12&" · "&B12)
A13: GER-P009 | I13: =IF(OR(G13="",H13=""),"",G13*H13) | J13: =IF(I13="","",IF(I13>=15,"Crítica",IF(I13>=9,"Alta",IF(I13>=4,"Média","Baixa")))) | N13: =IF(B13="","",COUNTIF('Geral - Soluções'!$C$5:$C$500,A13&"*")) | R13: =IF(B13="","",A13&" · "&B13)
A14: GER-P010 | I14: =IF(OR(G14="",H14=""),"",G14*H14) | J14: =IF(I14="","",IF(I14>=15,"Crítica",IF(I14>=9,"Alta",IF(I14>=4,"Média","Baixa")))) | N14: =IF(B14="","",COUNTIF('Geral - Soluções'!$C$5:$C$500,A14&"*")) | R14: =IF(B14="","",A14&" · "&B14)
A15: GER-P011 | I15: =IF(OR(G15="",H15=""),"",G15*H15) | J15: =IF(I15="","",IF(I15>=15,"Crítica",IF(I15>=9,"Alta",IF(I15>=4,"Média","Baixa")))) | N15: =IF(B15="","",COUNTIF('Geral - Soluções'!$C$5:$C$500,A15&"*")) | R15: =IF(B15="","",A15&" · "&B15)
A16: GER-P012 | I16: =IF(OR(G16="",H16=""),"",G16*H16) | J16: =IF(I16="","",IF(I16>=15,"Crítica",IF(I16>=9,"Alta",IF(I16>=4,"Média","Baixa")))) | N16: =IF(B16="","",COUNTIF('Geral - Soluções'!$C$5:$C$500,A16&"*")) | R16: =IF(B16="","",A16&" · "&B16)
A17: GER-P013 | I17: =IF(OR(G17="",H17=""),"",G17*H17) | J17: =IF(I17="","",IF(I17>=15,"Crítica",IF(I17>=9,"Alta",IF(I17>=4,"Média","Baixa")))) | N17: =IF(B17="","",COUNTIF('Geral - Soluções'!$C$5:$C$500,A17&"*")) | R17: =IF(B17="","",A17&" · "&B17)
... A104: GER-P100 | I104: =IF(OR(G104="",H104=""),"",G104*H104) | J104: =IF(I104="","",IF(I104>=15,"Crítica",IF(I104>=9,"Alta",IF(I104>=4,"Média","Baixa")))) | N104: =IF(B104="","",COUNTIF('Geral - Soluções'!$C$5:$C$500,A104&"*")) | R104: =IF(B104="","",A104&" · "&B104)

Sheet Geral - Soluções
A1: ⬢ CEMP · Geral — Soluções
A2: ← Início | B2: ="Soluções encontradas em outros projetos/empresas para: Geral (CEMP inteiro) · "&COUNTA(B5:B500)&" registro(s)" -> Soluções encontradas em outros projetos/empresas para: Geral (CEMP inteiro) · 1 registro(s)
A3: A SOLUÇÃO | E3: DE ONDE VEIO | H3: COMO IMPLANTAR | K3: VIABILIDADE | N3: EVIDÊNCIAS | P3: ACOMPANHAMENTO | S3: REGISTRO
A4: ID | B4: Nome da solução / prática | C4: Problema que resolve | D4: O que é a solução | E4: Fonte (organização) | F4: Tipo de fonte (auto) | G4: Como descobrimos | H4: Como implantar (passo a passo) | I4: Recursos necessários (pessoas, tempo, ferramentas) | J4: Custo estimado (R$) | K4: Esforço de implantação | L4: Impacto esperado | M4: Análise (auto) | N4: Dados / resultados da solução | O4: Link / referência | P4: Status de implantação | Q4: Responsável | R4: Prazo previsto | S4: Riscos / lições / observações | T4: Data de registro | U4: Registrado por
A5: GER-S001 | B5: [EXEMPLO] Programa de onboarding com padrinhos | C5: GER-P001 · [EXEMPLO] Baixa retenção de membros após o processo seletivo | D5: Cada novo membro é acompanhado por um membro mais experiente nos primeiros 90 dias, com metas e check-ins definidos. | E5: FNT-001 · [EXEMPLO] Empresa Júnior de Administração – Universidade X | F5: =IF(E5="","",IFERROR(INDEX('Fontes e Parcerias'!$C$5:$C$500,MATCH(IFERROR(LEFT(E5,FIND(" · ",E5)-1),E5),'Fontes e Parcerias'!$A$5:$A$500,0)),"Fonte não encontrada")) -> Empresa Júnior | G5: Conversa / reunião | H5: 1) Definir critérios para escolher os padrinhos. 2) Montar um roteiro de 90 dias (semana 1, 30, 60 e 90). 3) Agendar check-ins quinzenais. 4) Medir a retenção no fim do semestre. | I5: 1 responsável na diretoria + planilha de acompanhamento | J5: 0 | K5: Baixo | L5: Alto | M5: =IF(OR(K5="",L5=""),"",IF((IF(L5="Alto",3,IF(L5="Médio",2,1))-IF(K5="Alto",3,IF(K5="Médio",2,1)))=2,"⚡ Quick win",IF((IF(L5="Alto",3,IF(L5="Médio",2,1))-IF(K5="Alto",3,IF(K5="Médio",2,1)))=1,"🚀 Alto retorno",IF(AND(L5="Alto",K5="Alto"),"🎯 Estratégica",IF((IF(L5="Alto",3,IF(L5="Médio",2,1))-IF(K5="Alto",3,IF(K5="Médio",2,1)))=0,"⚖ Equilibrada","⏳ Baixo retorno"))))) -> ⚡ Quick win | N5: [Dado ilustrativo] Registre aqui os números que a fonte compartilhou (ex.: retenção antes/depois). | O5: (cole aqui o link do material ou do perfil da fonte) | P5: Em análise | Q5: Nome do responsável | R5: 46338 | S5: Linha de exemplo — apague ou sobrescreva. | T5: 46293 | U5: Diretoria de P&D
A6: GER-S002 | F6: =IF(E6="","",IFERROR(INDEX('Fontes e Parcerias'!$C$5:$C$500,MATCH(IFERROR(LEFT(E6,FIND(" · ",E6)-1),E6),'Fontes e Parcerias'!$A$5:$A$500,0)),"Fonte não encontrada")) | M6: =IF(OR(K6="",L6=""),"",IF((IF(L6="Alto",3,IF(L6="Médio",2,1))-IF(K6="Alto",3,IF(K6="Médio",2,1)))=2,"⚡ Quick win",IF((IF(L6="Alto",3,IF(L6="Médio",2,1))-IF(K6="Alto",3,IF(K6="Médio",2,1)))=1,"🚀 Alto retorno",IF(AND(L6="Alto",K6="Alto"),"🎯 Estratégica",IF((IF(L6="Alto",3,IF(L6="Médio",2,1))-IF(K6="Alto",3,IF(K6="Médio",2,1)))=0,"⚖ Equilibrada","⏳ Baixo retorno")))))
A7: GER-S003 | F7: =IF(E7="","",IFERROR(INDEX('Fontes e Parcerias'!$C$5:$C$500,MATCH(IFERROR(LEFT(E7,FIND(" · ",E7)-1),E7),'Fontes e Parcerias'!$A$5:$A$500,0)),"Fonte não encontrada")) | M7: =IF(OR(K7="",L7=""),"",IF((IF(L7="Alto",3,IF(L7="Médio",2,1))-IF(K7="Alto",3,IF(K7="Médio",2,1)))=2,"⚡ Quick win",IF((IF(L7="Alto",3,IF(L7="Médio",2,1))-IF(K7="Alto",3,IF(K7="Médio",2,1)))=1,"🚀 Alto retorno",IF(AND(L7="Alto",K7="Alto"),"🎯 Estratégica",IF((IF(L7="Alto",3,IF(L7="Médio",2,1))-IF(K7="Alto",3,IF(K7="Médio",2,1)))=0,"⚖ Equilibrada","⏳ Baixo retorno")))))
A8: GER-S004 | F8: =IF(E8="","",IFERROR(INDEX('Fontes e Parcerias'!$C$5:$C$500,MATCH(IFERROR(LEFT(E8,FIND(" · ",E8)-1),E8),'Fontes e Parcerias'!$A$5:$A$500,0)),"Fonte não encontrada")) | M8: =IF(OR(K8="",L8=""),"",IF((IF(L8="Alto",3,IF(L8="Médio",2,1))-IF(K8="Alto",3,IF(K8="Médio",2,1)))=2,"⚡ Quick win",IF((IF(L8="Alto",3,IF(L8="Médio",2,1))-IF(K8="Alto",3,IF(K8="Médio",2,1)))=1,"🚀 Alto retorno",IF(AND(L8="Alto",K8="Alto"),"🎯 Estratégica",IF((IF(L8="Alto",3,IF(L8="Médio",2,1))-IF(K8="Alto",3,IF(K8="Médio",2,1)))=0,"⚖ Equilibrada","⏳ Baixo retorno")))))
A9: GER-S005 | F9: =IF(E9="","",IFERROR(INDEX('Fontes e Parcerias'!$C$5:$C$500,MATCH(IFERROR(LEFT(E9,FIND(" · ",E9)-1),E9),'Fontes e Parcerias'!$A$5:$A$500,0)),"Fonte não encontrada")) | M9: =IF(OR(K9="",L9=""),"",IF((IF(L9="Alto",3,IF(L9="Médio",2,1))-IF(K9="Alto",3,IF(K9="Médio",2,1)))=2,"⚡ Quick win",IF((IF(L9="Alto",3,IF(L9="Médio",2,1))-IF(K9="Alto",3,IF(K9="Médio",2,1)))=1,"🚀 Alto retorno",IF(AND(L9="Alto",K9="Alto"),"🎯 Estratégica",IF((IF(L9="Alto",3,IF(L9="Médio",2,1))-IF(K9="Alto",3,IF(K9="Médio",2,1)))=0,"⚖ Equilibrada","⏳ Baixo retorno")))))
A10: GER-S006 | F10: =IF(E10="","",IFERROR(INDEX('Fontes e Parcerias'!$C$5:$C$500,MATCH(IFERROR(LEFT(E10,FIND(" · ",E10)-1),E10),'Fontes e Parcerias'!$A$5:$A$500,0)),"Fonte não encontrada")) | M10: =IF(OR(K10="",L10=""),"",IF((IF(L10="Alto",3,IF(L10="Médio",2,1))-IF(K10="Alto",3,IF(K10="Médio",2,1)))=2,"⚡ Quick win",IF((IF(L10="Alto",3,IF(L10="Médio",2,1))-IF(K10="Alto",3,IF(K10="Médio",2,1)))=1,"🚀 Alto retorno",IF(AND(L10="Alto",K10="Alto"),"🎯 Estratégica",IF((IF(L10="Alto",3,IF(L10="Médio",2,1))-IF(K10="Alto",3,IF(K10="Médio",2,1)))=0,"⚖ Equilibrada","⏳ Baixo retorno")))))
A11: GER-S007 | F11: =IF(E11="","",IFERROR(INDEX('Fontes e Parcerias'!$C$5:$C$500,MATCH(IFERROR(LEFT(E11,FIND(" · ",E11)-1),E11),'Fontes e Parcerias'!$A$5:$A$500,0)),"Fonte não encontrada")) | M11: =IF(OR(K11="",L11=""),"",IF((IF(L11="Alto",3,IF(L11="Médio",2,1))-IF(K11="Alto",3,IF(K11="Médio",2,1)))=2,"⚡ Quick win",IF((IF(L11="Alto",3,IF(L11="Médio",2,1))-IF(K11="Alto",3,IF(K11="Médio",2,1)))=1,"🚀 Alto retorno",IF(AND(L11="Alto",K11="Alto"),"🎯 Estratégica",IF((IF(L11="Alto",3,IF(L11="Médio",2,1))-IF(K11="Alto",3,IF(K11="Médio",2,1)))=0,"⚖ Equilibrada","⏳ Baixo retorno")))))
A12: GER-S008 | F12: =IF(E12="","",IFERROR(INDEX('Fontes e Parcerias'!$C$5:$C$500,MATCH(IFERROR(LEFT(E12,FIND(" · ",E12)-1),E12),'Fontes e Parcerias'!$A$5:$A$500,0)),"Fonte não encontrada")) | M12: =IF(OR(K12="",L12=""),"",IF((IF(L12="Alto",3,IF(L12="Médio",2,1))-IF(K12="Alto",3,IF(K12="Médio",2,1)))=2,"⚡ Quick win",IF((IF(L12="Alto",3,IF(L12="Médio",2,1))-IF(K12="Alto",3,IF(K12="Médio",2,1)))=1,"🚀 Alto retorno",IF(AND(L12="Alto",K12="Alto"),"🎯 Estratégica",IF((IF(L12="Alto",3,IF(L12="Médio",2,1))-IF(K12="Alto",3,IF(K12="Médio",2,1)))=0,"⚖ Equilibrada","⏳ Baixo retorno")))))
A13: GER-S009 | F13: =IF(E13="","",IFERROR(INDEX('Fontes e Parcerias'!$C$5:$C$500,MATCH(IFERROR(LEFT(E13,FIND(" · ",E13)-1),E13),'Fontes e Parcerias'!$A$5:$A$500,0)),"Fonte não encontrada")) | M13: =IF(OR(K13="",L13=""),"",IF((IF(L13="Alto",3,IF(L13="Médio",2,1))-IF(K13="Alto",3,IF(K13="Médio",2,1)))=2,"⚡ Quick win",IF((IF(L13="Alto",3,IF(L13="Médio",2,1))-IF(K13="Alto",3,IF(K13="Médio",2,1)))=1,"🚀 Alto retorno",IF(AND(L13="Alto",K13="Alto"),"🎯 Estratégica",IF((IF(L13="Alto",3,IF(L13="Médio",2,1))-IF(K13="Alto",3,IF(K13="Médio",2,1)))=0,"⚖ Equilibrada","⏳ Baixo retorno")))))
A14: GER-S010 | F14: =IF(E14="","",IFERROR(INDEX('Fontes e Parcerias'!$C$5:$C$500,MATCH(IFERROR(LEFT(E14,FIND(" · ",E14)-1),E14),'Fontes e Parcerias'!$A$5:$A$500,0)),"Fonte não encontrada")) | M14: =IF(OR(K14="",L14=""),"",IF((IF(L14="Alto",3,IF(L14="Médio",2,1))-IF(K14="Alto",3,IF(K14="Médio",2,1)))=2,"⚡ Quick win",IF((IF(L14="Alto",3,IF(L14="Médio",2,1))-IF(K14="Alto",3,IF(K14="Médio",2,1)))=1,"🚀 Alto retorno",IF(AND(L14="Alto",K14="Alto"),"🎯 Estratégica",IF((IF(L14="Alto",3,IF(L14="Médio",2,1))-IF(K14="Alto",3,IF(K14="Médio",2,1)))=0,"⚖ Equilibrada","⏳ Baixo retorno")))))
A15: GER-S011 | F15: =IF(E15="","",IFERROR(INDEX('Fontes e Parcerias'!$C$5:$C$500,MATCH(IFERROR(LEFT(E15,FIND(" · ",E15)-1),E15),'Fontes e Parcerias'!$A$5:$A$500,0)),"Fonte não encontrada")) | M15: =IF(OR(K15="",L15=""),"",IF((IF(L15="Alto",3,IF(L15="Médio",2,1))-IF(K15="Alto",3,IF(K15="Médio",2,1)))=2,"⚡ Quick win",IF((IF(L15="Alto",3,IF(L15="Médio",2,1))-IF(K15="Alto",3,IF(K15="Médio",2,1)))=1,"🚀 Alto retorno",IF(AND(L15="Alto",K15="Alto"),"🎯 Estratégica",IF((IF(L15="Alto",3,IF(L15="Médio",2,1))-IF(K15="Alto",3,IF(K15="Médio",2,1)))=0,"⚖ Equilibrada","⏳ Baixo retorno")))))
A16: GER-S012 | F16: =IF(E16="","",IFERROR(INDEX('Fontes e Parcerias'!$C$5:$C$500,MATCH(IFERROR(LEFT(E16,FIND(" · ",E16)-1),E16),'Fontes e Parcerias'!$A$5:$A$500,0)),"Fonte não encontrada")) | M16: =IF(OR(K16="",L16=""),"",IF((IF(L16="Alto",3,IF(L16="Médio",2,1))-IF(K16="Alto",3,IF(K16="Médio",2,1)))=2,"⚡ Quick win",IF((IF(L16="Alto",3,IF(L16="Médio",2,1))-IF(K16="Alto",3,IF(K16="Médio",2,1)))=1,"🚀 Alto retorno",IF(AND(L16="Alto",K16="Alto"),"🎯 Estratégica",IF((IF(L16="Alto",3,IF(L16="Médio",2,1))-IF(K16="Alto",3,IF(K16="Médio",2,1)))=0,"⚖ Equilibrada","⏳ Baixo retorno")))))
A17: GER-S013 | F17: =IF(E17="","",IFERROR(INDEX('Fontes e Parcerias'!$C$5:$C$500,MATCH(IFERROR(LEFT(E17,FIND(" · ",E17)-1),E17),'Fontes e Parcerias'!$A$5:$A$500,0)),"Fonte não encontrada")) | M17: =IF(OR(K17="",L17=""),"",IF((IF(L17="Alto",3,IF(L17="Médio",2,1))-IF(K17="Alto",3,IF(K17="Médio",2,1)))=2,"⚡ Quick win",IF((IF(L17="Alto",3,IF(L17="Médio",2,1))-IF(K17="Alto",3,IF(K17="Médio",2,1)))=1,"🚀 Alto retorno",IF(AND(L17="Alto",K17="Alto"),"🎯 Estratégica",IF((IF(L17="Alto",3,IF(L17="Médio",2,1))-IF(K17="Alto",3,IF(K17="Médio",2,1)))=0,"⚖ Equilibrada","⏳ Baixo retorno")))))
... A104: GER-S100 | F104: =IF(E104="","",IFERROR(INDEX('Fontes e Parcerias'!$C$5:$C$500,MATCH(IFERROR(LEFT(E104,FIND(" · ",E104)-1),E104),'Fontes e Parcerias'!$A$5:$A$500,0)),"Fonte não encontrada")) | M104: =IF(OR(K104="",L104=""),"",IF((IF(L104="Alto",3,IF(L104="Médio",2,1))-IF(K104="Alto",3,IF(K104="Médio",2,1)))=2,"⚡ Quick win",IF((IF(L104="Alto",3,IF(L104="Médio",2,1))-IF(K104="Alto",3,IF(K104="Médio",2,1)))=1,"🚀 Alto retorno",IF(AND(L104="Alto",K104="Alto"),"🎯 Estratégica",IF((IF(L104="Alto",3,IF(L104="Médio",2,1))-IF(K104="Alto",3,IF(K104="Médio",2,1)))=0,"⚖ Equilibrada","⏳ Baixo retorno")))))

Sheet Mentoring - Problemas
A1: ⬢ CEMP · Mentoring — Problemas
A2: ← Início | B2: ="Problemas que o CEMP tem ou pode ter em: Mentoring · "&COUNTA(B5:B500)&" registro(s)" -> Problemas que o CEMP tem ou pode ter em: Mentoring · 1 registro(s)
A3: O PROBLEMA | G3: AVALIAÇÃO DE RISCO | K3: GESTÃO | O3: REGISTRO
A4: ID | B4: Título do problema | C4: Descrição detalhada | D4: Categoria | E4: Situação | F4: Etapa / momento em que ocorre | G4: Impacto (1–5) | H4: Probabilidade (1–5) | I4: Score (auto) | J4: Prioridade (auto) | K4: Evidência / como identificamos | L4: Diretoria responsável | M4: Status | N4: Soluções vinculadas (auto) | O4: Data de registro | P4: Registrado por | Q4: Observações | R4: Rótulo p/ vínculo (auto)
A5: MEN-P001 | B5: [EXEMPLO] Desistência de mentorados ao longo do ciclo | C5: Mentorados perdem o ritmo após as primeiras semanas e deixam de comparecer às sessões. | D5: Público e adesão | E5: Ocorrendo hoje | F5: Meio do ciclo de mentoria | G5: 4 | H5: 3 | I5: =IF(OR(G5="",H5=""),"",G5*H5) -> 12 | J5: =IF(I5="","",IF(I5>=15,"Crítica",IF(I5>=9,"Alta",IF(I5>=4,"Média","Baixa")))) -> Alta | K5: Comparar lista de presença da 1ª e da última sessão. | L5: Projetos | M5: Em análise | N5: =IF(B5="","",COUNTIF('Mentoring - Soluções'!$C$5:$C$500,A5&"*")) -> 1 | O5: 46293 | P5: Diretoria de P&D | Q5: Linha de exemplo — apague ou sobrescreva. | R5: =IF(B5="","",A5&" · "&B5) -> MEN-P001 · [EXEMPLO] Desistência de mentorados ao longo do ciclo
A6: MEN-P002 | I6: =IF(OR(G6="",H6=""),"",G6*H6) | J6: =IF(I6="","",IF(I6>=15,"Crítica",IF(I6>=9,"Alta",IF(I6>=4,"Média","Baixa")))) | N6: =IF(B6="","",COUNTIF('Mentoring - Soluções'!$C$5:$C$500,A6&"*")) | R6: =IF(B6="","",A6&" · "&B6)
A7: MEN-P003 | I7: =IF(OR(G7="",H7=""),"",G7*H7) | J7: =IF(I7="","",IF(I7>=15,"Crítica",IF(I7>=9,"Alta",IF(I7>=4,"Média","Baixa")))) | N7: =IF(B7="","",COUNTIF('Mentoring - Soluções'!$C$5:$C$500,A7&"*")) | R7: =IF(B7="","",A7&" · "&B7)
A8: MEN-P004 | I8: =IF(OR(G8="",H8=""),"",G8*H8) | J8: =IF(I8="","",IF(I8>=15,"Crítica",IF(I8>=9,"Alta",IF(I8>=4,"Média","Baixa")))) | N8: =IF(B8="","",COUNTIF('Mentoring - Soluções'!$C$5:$C$500,A8&"*")) | R8: =IF(B8="","",A8&" · "&B8)
A9: MEN-P005 | I9: =IF(OR(G9="",H9=""),"",G9*H9) | J9: =IF(I9="","",IF(I9>=15,"Crítica",IF(I9>=9,"Alta",IF(I9>=4,"Média","Baixa")))) | N9: =IF(B9="","",COUNTIF('Mentoring - Soluções'!$C$5:$C$500,A9&"*")) | R9: =IF(B9="","",A9&" · "&B9)
A10: MEN-P006 | I10: =IF(OR(G10="",H10=""),"",G10*H10) | J10: =IF(I10="","",IF(I10>=15,"Crítica",IF(I10>=9,"Alta",IF(I10>=4,"Média","Baixa")))) | N10: =IF(B10="","",COUNTIF('Mentoring - Soluções'!$C$5:$C$500,A10&"*")) | R10: =IF(B10="","",A10&" · "&B10)
A11: MEN-P007 | I11: =IF(OR(G11="",H11=""),"",G11*H11) | J11: =IF(I11="","",IF(I11>=15,"Crítica",IF(I11>=9,"Alta",IF(I11>=4,"Média","Baixa")))) | N11: =IF(B11="","",COUNTIF('Mentoring - Soluções'!$C$5:$C$500,A11&"*")) | R11: =IF(B11="","",A11&" · "&B11)
A12: MEN-P008 | I12: =IF(OR(G12="",H12=""),"",G12*H12) | J12: =IF(I12="","",IF(I12>=15,"Crítica",IF(I12>=9,"Alta",IF(I12>=4,"Média","Baixa")))) | N12: =IF(B12="","",COUNTIF('Mentoring - Soluções'!$C$5:$C$500,A12&"*")) | R12: =IF(B12="","",A12&" · "&B12)
A13: MEN-P009 | I13: =IF(OR(G13="",H13=""),"",G13*H13) | J13: =IF(I13="","",IF(I13>=15,"Crítica",IF(I13>=9,"Alta",IF(I13>=4,"Média","Baixa")))) | N13: =IF(B13="","",COUNTIF('Mentoring - Soluções'!$C$5:$C$500,A13&"*")) | R13: =IF(B13="","",A13&" · "&B13)
A14: MEN-P010 | I14: =IF(OR(G14="",H14=""),"",G14*H14) | J14: =IF(I14="","",IF(I14>=15,"Crítica",IF(I14>=9,"Alta",IF(I14>=4,"Média","Baixa")))) | N14: =IF(B14="","",COUNTIF('Mentoring - Soluções'!$C$5:$C$500,A14&"*")) | R14: =IF(B14="","",A14&" · "&B14)
A15: MEN-P011 | I15: =IF(OR(G15="",H15=""),"",G15*H15) | J15: =IF(I15="","",IF(I15>=15,"Crítica",IF(I15>=9,"Alta",IF(I15>=4,"Média","Baixa")))) | N15: =IF(B15="","",COUNTIF('Mentoring - Soluções'!$C$5:$C$500,A15&"*")) | R15: =IF(B15="","",A15&" · "&B15)
A16: MEN-P012 | I16: =IF(OR(G16="",H16=""),"",G16*H16) | J16: =IF(I16="","",IF(I16>=15,"Crítica",IF(I16>=9,"Alta",IF(I16>=4,"Média","Baixa")))) | N16: =IF(B16="","",COUNTIF('Mentoring - Soluções'!$C$5:$C$500,A16&"*")) | R16: =IF(B16="","",A16&" · "&B16)
A17: MEN-P013 | I17: =IF(OR(G17="",H17=""),"",G17*H17) | J17: =IF(I17="","",IF(I17>=15,"Crítica",IF(I17>=9,"Alta",IF(I17>=4,"Média","Baixa")))) | N17: =IF(B17="","",COUNTIF('Mentoring - Soluções'!$C$5:$C$500,A17&"*")) | R17: =IF(B17="","",A17&" · "&B17)
... A104: MEN-P100 | I104: =IF(OR(G104="",H104=""),"",G104*H104) | J104: =IF(I104="","",IF(I104>=15,"Crítica",IF(I104>=9,"Alta",IF(I104>=4,"Média","Baixa")))) | N104: =IF(B104="","",COUNTIF('Mentoring - Soluções'!$C$5:$C$500,A104&"*")) | R104: =IF(B104="","",A104&" · "&B104)

Sheet Mentoring - Soluções
A1: ⬢ CEMP · Mentoring — Soluções
A2: ← Início | B2: ="Soluções encontradas em outros projetos/empresas para: Mentoring · "&COUNTA(B5:B500)&" registro(s)" -> Soluções encontradas em outros projetos/empresas para: Mentoring · 1 registro(s)
A3: A SOLUÇÃO | E3: DE ONDE VEIO | H3: COMO IMPLANTAR | K3: VIABILIDADE | N3: EVIDÊNCIAS | P3: ACOMPANHAMENTO | S3: REGISTRO
A4: ID | B4: Nome da solução / prática | C4: Problema que resolve | D4: O que é a solução | E4: Fonte (organização) | F4: Tipo de fonte (auto) | G4: Como descobrimos | H4: Como implantar (passo a passo) | I4: Recursos necessários (pessoas, tempo, ferramentas) | J4: Custo estimado (R$) | K4: Esforço de implantação | L4: Impacto esperado | M4: Análise (auto) | N4: Dados / resultados da solução | O4: Link / referência | P4: Status de implantação | Q4: Responsável | R4: Prazo previsto | S4: Riscos / lições / observações | T4: Data de registro | U4: Registrado por
A5: MEN-S001 | B5: [EXEMPLO] Check-ins quinzenais com formulário rápido | C5: MEN-P001 · [EXEMPLO] Desistência de mentorados ao longo do ciclo | D5: Formulário de 2 minutos após cada sessão para medir presença, evolução e satisfação, com alerta para quem faltar duas vezes. | E5: FNT-001 · [EXEMPLO] Empresa Júnior de Administração – Universidade X | F5: =IF(E5="","",IFERROR(INDEX('Fontes e Parcerias'!$C$5:$C$500,MATCH(IFERROR(LEFT(E5,FIND(" · ",E5)-1),E5),'Fontes e Parcerias'!$A$5:$A$500,0)),"Fonte não encontrada")) -> Empresa Júnior | G5: Conversa / reunião | H5: 1) Criar formulário com 5 perguntas. 2) Enviar após cada sessão. 3) Revisar as respostas a cada 15 dias. 4) Contatar quem faltou duas vezes seguidas. | I5: Formulário online + 1 membro para acompanhar | J5: 0 | K5: Baixo | L5: Médio | M5: =IF(OR(K5="",L5=""),"",IF((IF(L5="Alto",3,IF(L5="Médio",2,1))-IF(K5="Alto",3,IF(K5="Médio",2,1)))=2,"⚡ Quick win",IF((IF(L5="Alto",3,IF(L5="Médio",2,1))-IF(K5="Alto",3,IF(K5="Médio",2,1)))=1,"🚀 Alto retorno",IF(AND(L5="Alto",K5="Alto"),"🎯 Estratégica",IF((IF(L5="Alto",3,IF(L5="Médio",2,1))-IF(K5="Alto",3,IF(K5="Médio",2,1)))=0,"⚖ Equilibrada","⏳ Baixo retorno"))))) -> 🚀 Alto retorno | N5: [Dado ilustrativo] Registre aqui presença média e satisfação relatadas pela fonte. | O5: (cole aqui o link) | P5: Ideia | Q5: Nome do responsável | R5: 46338 | S5: Linha de exemplo — apague ou sobrescreva. | T5: 46293 | U5: Diretoria de P&D
A6: MEN-S002 | F6: =IF(E6="","",IFERROR(INDEX('Fontes e Parcerias'!$C$5:$C$500,MATCH(IFERROR(LEFT(E6,FIND(" · ",E6)-1),E6),'Fontes e Parcerias'!$A$5:$A$500,0)),"Fonte não encontrada")) | M6: =IF(OR(K6="",L6=""),"",IF((IF(L6="Alto",3,IF(L6="Médio",2,1))-IF(K6="Alto",3,IF(K6="Médio",2,1)))=2,"⚡ Quick win",IF((IF(L6="Alto",3,IF(L6="Médio",2,1))-IF(K6="Alto",3,IF(K6="Médio",2,1)))=1,"🚀 Alto retorno",IF(AND(L6="Alto",K6="Alto"),"🎯 Estratégica",IF((IF(L6="Alto",3,IF(L6="Médio",2,1))-IF(K6="Alto",3,IF(K6="Médio",2,1)))=0,"⚖ Equilibrada","⏳ Baixo retorno")))))
A7: MEN-S003 | F7: =IF(E7="","",IFERROR(INDEX('Fontes e Parcerias'!$C$5:$C$500,MATCH(IFERROR(LEFT(E7,FIND(" · ",E7)-1),E7),'Fontes e Parcerias'!$A$5:$A$500,0)),"Fonte não encontrada")) | M7: =IF(OR(K7="",L7=""),"",IF((IF(L7="Alto",3,IF(L7="Médio",2,1))-IF(K7="Alto",3,IF(K7="Médio",2,1)))=2,"⚡ Quick win",IF((IF(L7="Alto",3,IF(L7="Médio",2,1))-IF(K7="Alto",3,IF(K7="Médio",2,1)))=1,"🚀 Alto retorno",IF(AND(L7="Alto",K7="Alto"),"🎯 Estratégica",IF((IF(L7="Alto",3,IF(L7="Médio",2,1))-IF(K7="Alto",3,IF(K7="Médio",2,1)))=0,"⚖ Equilibrada","⏳ Baixo retorno")))))
A8: MEN-S004 | F8: =IF(E8="","",IFERROR(INDEX('Fontes e Parcerias'!$C$5:$C$500,MATCH(IFERROR(LEFT(E8,FIND(" · ",E8)-1),E8),'Fontes e Parcerias'!$A$5:$A$500,0)),"Fonte não encontrada")) | M8: =IF(OR(K8="",L8=""),"",IF((IF(L8="Alto",3,IF(L8="Médio",2,1))-IF(K8="Alto",3,IF(K8="Médio",2,1)))=2,"⚡ Quick win",IF((IF(L8="Alto",3,IF(L8="Médio",2,1))-IF(K8="Alto",3,IF(K8="Médio",2,1)))=1,"🚀 Alto retorno",IF(AND(L8="Alto",K8="Alto"),"🎯 Estratégica",IF((IF(L8="Alto",3,IF(L8="Médio",2,1))-IF(K8="Alto",3,IF(K8="Médio",2,1)))=0,"⚖ Equilibrada","⏳ Baixo retorno")))))
A9: MEN-S005 | F9: =IF(E9="","",IFERROR(INDEX('Fontes e Parcerias'!$C$5:$C$500,MATCH(IFERROR(LEFT(E9,FIND(" · ",E9)-1),E9),'Fontes e Parcerias'!$A$5:$A$500,0)),"Fonte não encontrada")) | M9: =IF(OR(K9="",L9=""),"",IF((IF(L9="Alto",3,IF(L9="Médio",2,1))-IF(K9="Alto",3,IF(K9="Médio",2,1)))=2,"⚡ Quick win",IF((IF(L9="Alto",3,IF(L9="Médio",2,1))-IF(K9="Alto",3,IF(K9="Médio",2,1)))=1,"🚀 Alto retorno",IF(AND(L9="Alto",K9="Alto"),"🎯 Estratégica",IF((IF(L9="Alto",3,IF(L9="Médio",2,1))-IF(K9="Alto",3,IF(K9="Médio",2,1)))=0,"⚖ Equilibrada","⏳ Baixo retorno")))))
A10: MEN-S006 | F10: =IF(E10="","",IFERROR(INDEX('Fontes e Parcerias'!$C$5:$C$500,MATCH(IFERROR(LEFT(E10,FIND(" · ",E10)-1),E10),'Fontes e Parcerias'!$A$5:$A$500,0)),"Fonte não encontrada")) | M10: =IF(OR(K10="",L10=""),"",IF((IF(L10="Alto",3,IF(L10="Médio",2,1))-IF(K10="Alto",3,IF(K10="Médio",2,1)))=2,"⚡ Quick win",IF((IF(L10="Alto",3,IF(L10="Médio",2,1))-IF(K10="Alto",3,IF(K10="Médio",2,1)))=1,"🚀 Alto retorno",IF(AND(L10="Alto",K10="Alto"),"🎯 Estratégica",IF((IF(L10="Alto",3,IF(L10="Médio",2,1))-IF(K10="Alto",3,IF(K10="Médio",2,1)))=0,"⚖ Equilibrada","⏳ Baixo retorno")))))
A11: MEN-S007 | F11: =IF(E11="","",IFERROR(INDEX('Fontes e Parcerias'!$C$5:$C$500,MATCH(IFERROR(LEFT(E11,FIND(" · ",E11)-1),E11),'Fontes e Parcerias'!$A$5:$A$500,0)),"Fonte não encontrada")) | M11: =IF(OR(K11="",L11=""),"",IF((IF(L11="Alto",3,IF(L11="Médio",2,1))-IF(K11="Alto",3,IF(K11="Médio",2,1)))=2,"⚡ Quick win",IF((IF(L11="Alto",3,IF(L11="Médio",2,1))-IF(K11="Alto",3,IF(K11="Médio",2,1)))=1,"🚀 Alto retorno",IF(AND(L11="Alto",K11="Alto"),"🎯 Estratégica",IF((IF(L11="Alto",3,IF(L11="Médio",2,1))-IF(K11="Alto",3,IF(K11="Médio",2,1)))=0,"⚖ Equilibrada","⏳ Baixo retorno")))))
A12: MEN-S008 | F12: =IF(E12="","",IFERROR(INDEX('Fontes e Parcerias'!$C$5:$C$500,MATCH(IFERROR(LEFT(E12,FIND(" · ",E12)-1),E12),'Fontes e Parcerias'!$A$5:$A$500,0)),"Fonte não encontrada")) | M12: =IF(OR(K12="",L12=""),"",IF((IF(L12="Alto",3,IF(L12="Médio",2,1))-IF(K12="Alto",3,IF(K12="Médio",2,1)))=2,"⚡ Quick win",IF((IF(L12="Alto",3,IF(L12="Médio",2,1))-IF(K12="Alto",3,IF(K12="Médio",2,1)))=1,"🚀 Alto retorno",IF(AND(L12="Alto",K12="Alto"),"🎯 Estratégica",IF((IF(L12="Alto",3,IF(L12="Médio",2,1))-IF(K12="Alto",3,IF(K12="Médio",2,1)))=0,"⚖ Equilibrada","⏳ Baixo retorno")))))
A13: MEN-S009 | F13: =IF(E13="","",IFERROR(INDEX('Fontes e Parcerias'!$C$5:$C$500,MATCH(IFERROR(LEFT(E13,FIND(" · ",E13)-1),E13),'Fontes e Parcerias'!$A$5:$A$500,0)),"Fonte não encontrada")) | M13: =IF(OR(K13="",L13=""),"",IF((IF(L13="Alto",3,IF(L13="Médio",2,1))-IF(K13="Alto",3,IF(K13="Médio",2,1)))=2,"⚡ Quick win",IF((IF(L13="Alto",3,IF(L13="Médio",2,1))-IF(K13="Alto",3,IF(K13="Médio",2,1)))=1,"🚀 Alto retorno",IF(AND(L13="Alto",K13="Alto"),"🎯 Estratégica",IF((IF(L13="Alto",3,IF(L13="Médio",2,1))-IF(K13="Alto",3,IF(K13="Médio",2,1)))=0,"⚖ Equilibrada","⏳ Baixo retorno")))))
A14: MEN-S010 | F14: =IF(E14="","",IFERROR(INDEX('Fontes e Parcerias'!$C$5:$C$500,MATCH(IFERROR(LEFT(E14,FIND(" · ",E14)-1),E14),'Fontes e Parcerias'!$A$5:$A$500,0)),"Fonte não encontrada")) | M14: =IF(OR(K14="",L14=""),"",IF((IF(L14="Alto",3,IF(L14="Médio",2,1))-IF(K14="Alto",3,IF(K14="Médio",2,1)))=2,"⚡ Quick win",IF((IF(L14="Alto",3,IF(L14="Médio",2,1))-IF(K14="Alto",3,IF(K14="Médio",2,1)))=1,"🚀 Alto retorno",IF(AND(L14="Alto",K14="Alto"),"🎯 Estratégica",IF((IF(L14="Alto",3,IF(L14="Médio",2,1))-IF(K14="Alto",3,IF(K14="Médio",2,1)))=0,"⚖ Equilibrada","⏳ Baixo retorno")))))
A15: MEN-S011 | F15: =IF(E15="","",IFERROR(INDEX('Fontes e Parcerias'!$C$5:$C$500,MATCH(IFERROR(LEFT(E15,FIND(" · ",E15)-1),E15),'Fontes e Parcerias'!$A$5:$A$500,0)),"Fonte não encontrada")) | M15: =IF(OR(K15="",L15=""),"",IF((IF(L15="Alto",3,IF(L15="Médio",2,1))-IF(K15="Alto",3,IF(K15="Médio",2,1)))=2,"⚡ Quick win",IF((IF(L15="Alto",3,IF(L15="Médio",2,1))-IF(K15="Alto",3,IF(K15="Médio",2,1)))=1,"🚀 Alto retorno",IF(AND(L15="Alto",K15="Alto"),"🎯 Estratégica",IF((IF(L15="Alto",3,IF(L15="Médio",2,1))-IF(K15="Alto",3,IF(K15="Médio",2,1)))=0,"⚖ Equilibrada","⏳ Baixo retorno")))))
A16: MEN-S012 | F16: =IF(E16="","",IFERROR(INDEX('Fontes e Parcerias'!$C$5:$C$500,MATCH(IFERROR(LEFT(E16,FIND(" · ",E16)-1),E16),'Fontes e Parcerias'!$A$5:$A$500,0)),"Fonte não encontrada")) | M16: =IF(OR(K16="",L16=""),"",IF((IF(L16="Alto",3,IF(L16="Médio",2,1))-IF(K16="Alto",3,IF(K16="Médio",2,1)))=2,"⚡ Quick win",IF((IF(L16="Alto",3,IF(L16="Médio",2,1))-IF(K16="Alto",3,IF(K16="Médio",2,1)))=1,"🚀 Alto retorno",IF(AND(L16="Alto",K16="Alto"),"🎯 Estratégica",IF((IF(L16="Alto",3,IF(L16="Médio",2,1))-IF(K16="Alto",3,IF(K16="Médio",2,1)))=0,"⚖ Equilibrada","⏳ Baixo retorno")))))
A17: MEN-S013 | F17: =IF(E17="","",IFERROR(INDEX('Fontes e Parcerias'!$C$5:$C$500,MATCH(IFERROR(LEFT(E17,FIND(" · ",E17)-1),E17),'Fontes e Parcerias'!$A$5:$A$500,0)),"Fonte não encontrada")) | M17: =IF(OR(K17="",L17=""),"",IF((IF(L17="Alto",3,IF(L17="Médio",2,1))-IF(K17="Alto",3,IF(K17="Médio",2,1)))=2,"⚡ Quick win",IF((IF(L17="Alto",3,IF(L17="Médio",2,1))-IF(K17="Alto",3,IF(K17="Médio",2,1)))=1,"🚀 Alto retorno",IF(AND(L17="Alto",K17="Alto"),"🎯 Estratégica",IF((IF(L17="Alto",3,IF(L17="Médio",2,1))-IF(K17="Alto",3,IF(K17="Médio",2,1)))=0,"⚖ Equilibrada","⏳ Baixo retorno")))))
... A104: MEN-S100 | F104: =IF(E104="","",IFERROR(INDEX('Fontes e Parcerias'!$C$5:$C$500,MATCH(IFERROR(LEFT(E104,FIND(" · ",E104)-1),E104),'Fontes e Parcerias'!$A$5:$A$500,0)),"Fonte não encontrada")) | M104: =IF(OR(K104="",L104=""),"",IF((IF(L104="Alto",3,IF(L104="Médio",2,1))-IF(K104="Alto",3,IF(K104="Médio",2,1)))=2,"⚡ Quick win",IF((IF(L104="Alto",3,IF(L104="Médio",2,1))-IF(K104="Alto",3,IF(K104="Médio",2,1)))=1,"🚀 Alto retorno",IF(AND(L104="Alto",K104="Alto"),"🎯 Estratégica",IF((IF(L104="Alto",3,IF(L104="Médio",2,1))-IF(K104="Alto",3,IF(K104="Médio",2,1)))=0,"⚖ Equilibrada","⏳ Baixo retorno")))))

Sheet Feira - Problemas
A1: ⬢ CEMP · Feira — Problemas
A2: ← Início | B2: ="Problemas que o CEMP tem ou pode ter em: Feira de Empreendedorismo · "&COUNTA(B5:B500)&" registro(s)" -> Problemas que o CEMP tem ou pode ter em: Feira de Empreendedorismo · 1 registro(s)
A3: O PROBLEMA | G3: AVALIAÇÃO DE RISCO | K3: GESTÃO | O3: REGISTRO
A4: ID | B4: Título do problema | C4: Descrição detalhada | D4: Categoria | E4: Situação | F4: Etapa / momento em que ocorre | G4: Impacto (1–5) | H4: Probabilidade (1–5) | I4: Score (auto) | J4: Prioridade (auto) | K4: Evidência / como identificamos | L4: Diretoria responsável | M4: Status | N4: Soluções vinculadas (auto) | O4: Data de registro | P4: Registrado por | Q4: Observações | R4: Rótulo p/ vínculo (auto)
A5: FEI-P001 | B5: [EXEMPLO] Dificuldade em captar patrocínio para a Feira | C5: Poucas empresas respondem aos pedidos de patrocínio e a negociação começa tarde. | D5: Captação de recursos e patrocínio | E5: Ocorrendo hoje | F5: Pré-evento (3 a 4 meses antes) | G5: 5 | H5: 4 | I5: =IF(OR(G5="",H5=""),"",G5*H5) -> 20 | J5: =IF(I5="","",IF(I5>=15,"Crítica",IF(I5>=9,"Alta",IF(I5>=4,"Média","Baixa")))) -> Crítica | K5: Taxa de resposta dos contatos da última edição. | L5: Parcerias | M5: Identificado | N5: =IF(B5="","",COUNTIF('Feira - Soluções'!$C$5:$C$500,A5&"*")) -> 1 | O5: 46293 | P5: Diretoria de P&D | Q5: Linha de exemplo — apague ou sobrescreva. | R5: =IF(B5="","",A5&" · "&B5) -> FEI-P001 · [EXEMPLO] Dificuldade em captar patrocínio para a Feira
A6: FEI-P002 | I6: =IF(OR(G6="",H6=""),"",G6*H6) | J6: =IF(I6="","",IF(I6>=15,"Crítica",IF(I6>=9,"Alta",IF(I6>=4,"Média","Baixa")))) | N6: =IF(B6="","",COUNTIF('Feira - Soluções'!$C$5:$C$500,A6&"*")) | R6: =IF(B6="","",A6&" · "&B6)
A7: FEI-P003 | I7: =IF(OR(G7="",H7=""),"",G7*H7) | J7: =IF(I7="","",IF(I7>=15,"Crítica",IF(I7>=9,"Alta",IF(I7>=4,"Média","Baixa")))) | N7: =IF(B7="","",COUNTIF('Feira - Soluções'!$C$5:$C$500,A7&"*")) | R7: =IF(B7="","",A7&" · "&B7)
A8: FEI-P004 | I8: =IF(OR(G8="",H8=""),"",G8*H8) | J8: =IF(I8="","",IF(I8>=15,"Crítica",IF(I8>=9,"Alta",IF(I8>=4,"Média","Baixa")))) | N8: =IF(B8="","",COUNTIF('Feira - Soluções'!$C$5:$C$500,A8&"*")) | R8: =IF(B8="","",A8&" · "&B8)
A9: FEI-P005 | I9: =IF(OR(G9="",H9=""),"",G9*H9) | J9: =IF(I9="","",IF(I9>=15,"Crítica",IF(I9>=9,"Alta",IF(I9>=4,"Média","Baixa")))) | N9: =IF(B9="","",COUNTIF('Feira - Soluções'!$C$5:$C$500,A9&"*")) | R9: =IF(B9="","",A9&" · "&B9)
A10: FEI-P006 | I10: =IF(OR(G10="",H10=""),"",G10*H10) | J10: =IF(I10="","",IF(I10>=15,"Crítica",IF(I10>=9,"Alta",IF(I10>=4,"Média","Baixa")))) | N10: =IF(B10="","",COUNTIF('Feira - Soluções'!$C$5:$C$500,A10&"*")) | R10: =IF(B10="","",A10&" · "&B10)
A11: FEI-P007 | I11: =IF(OR(G11="",H11=""),"",G11*H11) | J11: =IF(I11="","",IF(I11>=15,"Crítica",IF(I11>=9,"Alta",IF(I11>=4,"Média","Baixa")))) | N11: =IF(B11="","",COUNTIF('Feira - Soluções'!$C$5:$C$500,A11&"*")) | R11: =IF(B11="","",A11&" · "&B11)
A12: FEI-P008 | I12: =IF(OR(G12="",H12=""),"",G12*H12) | J12: =IF(I12="","",IF(I12>=15,"Crítica",IF(I12>=9,"Alta",IF(I12>=4,"Média","Baixa")))) | N12: =IF(B12="","",COUNTIF('Feira - Soluções'!$C$5:$C$500,A12&"*")) | R12: =IF(B12="","",A12&" · "&B12)
A13: FEI-P009 | I13: =IF(OR(G13="",H13=""),"",G13*H13) | J13: =IF(I13="","",IF(I13>=15,"Crítica",IF(I13>=9,"Alta",IF(I13>=4,"Média","Baixa")))) | N13: =IF(B13="","",COUNTIF('Feira - Soluções'!$C$5:$C$500,A13&"*")) | R13: =IF(B13="","",A13&" · "&B13)
A14: FEI-P010 | I14: =IF(OR(G14="",H14=""),"",G14*H14) | J14: =IF(I14="","",IF(I14>=15,"Crítica",IF(I14>=9,"Alta",IF(I14>=4,"Média","Baixa")))) | N14: =IF(B14="","",COUNTIF('Feira - Soluções'!$C$5:$C$500,A14&"*")) | R14: =IF(B14="","",A14&" · "&B14)
A15: FEI-P011 | I15: =IF(OR(G15="",H15=""),"",G15*H15) | J15: =IF(I15="","",IF(I15>=15,"Crítica",IF(I15>=9,"Alta",IF(I15>=4,"Média","Baixa")))) | N15: =IF(B15="","",COUNTIF('Feira - Soluções'!$C$5:$C$500,A15&"*")) | R15: =IF(B15="","",A15&" · "&B15)
A16: FEI-P012 | I16: =IF(OR(G16="",H16=""),"",G16*H16) | J16: =IF(I16="","",IF(I16>=15,"Crítica",IF(I16>=9,"Alta",IF(I16>=4,"Média","Baixa")))) | N16: =IF(B16="","",COUNTIF('Feira - Soluções'!$C$5:$C$500,A16&"*")) | R16: =IF(B16="","",A16&" · "&B16)
A17: FEI-P013 | I17: =IF(OR(G17="",H17=""),"",G17*H17) | J17: =IF(I17="","",IF(I17>=15,"Crítica",IF(I17>=9,"Alta",IF(I17>=4,"Média","Baixa")))) | N17: =IF(B17="","",COUNTIF('Feira - Soluções'!$C$5:$C$500,A17&"*")) | R17: =IF(B17="","",A17&" · "&B17)
